<?xml version="1.0" encoding="UTF-8"?>
<testng-results skipped="0" failed="2" total="2" passed="0">
  <reporter-output>
  </reporter-output>
  <suite name="Suite" duration-ms="49823" started-at="2015-10-14T07:41:25Z" finished-at="2015-10-14T07:42:15Z">
    <groups>
    </groups>
    <test name="Test" duration-ms="49823" started-at="2015-10-14T07:41:25Z" finished-at="2015-10-14T07:42:15Z">
      <class name="extentreports.extentreports.test2_VerifyTitle">
        <test-method status="FAIL" signature="verifyBlogTitle()[pri:0, instance:extentreports.extentreports.test2_VerifyTitle@49e4cb85]" name="verifyBlogTitle" duration-ms="24886" started-at="2015-10-14T13:11:49Z" finished-at="2015-10-14T13:12:14Z">
          <exception class="java.lang.AssertionError">
            <message>
              <![CDATA[expected [true] but found [false]]]>
            </message>
            <full-stacktrace>
              <![CDATA[java.lang.AssertionError: expected [true] but found [false]
	at org.testng.Assert.fail(Assert.java:94)
	at org.testng.Assert.failNotEquals(Assert.java:494)
	at org.testng.Assert.assertTrue(Assert.java:42)
	at org.testng.Assert.assertTrue(Assert.java:52)
	at extentreports.extentreports.test2_VerifyTitle.verifyBlogTitle(test2_VerifyTitle.java:42)
	at sun.reflect.NativeMethodAccessorImpl.invoke0(Native Method)
	at sun.reflect.NativeMethodAccessorImpl.invoke(NativeMethodAccessorImpl.java:62)
	at sun.reflect.DelegatingMethodAccessorImpl.invoke(DelegatingMethodAccessorImpl.java:43)
	at java.lang.reflect.Method.invoke(Method.java:483)
	at org.testng.internal.MethodInvocationHelper.invokeMethod(MethodInvocationHelper.java:84)
	at org.testng.internal.Invoker.invokeMethod(Invoker.java:714)
	at org.testng.internal.Invoker.invokeTestMethod(Invoker.java:901)
	at org.testng.internal.Invoker.invokeTestMethods(Invoker.java:1231)
	at org.testng.internal.TestMethodWorker.invokeTestMethods(TestMethodWorker.java:127)
	at org.testng.internal.TestMethodWorker.run(TestMethodWorker.java:111)
	at org.testng.TestRunner.privateRun(TestRunner.java:767)
	at org.testng.TestRunner.run(TestRunner.java:617)
	at org.testng.SuiteRunner.runTest(SuiteRunner.java:334)
	at org.testng.SuiteRunner.runSequentially(SuiteRunner.java:329)
	at org.testng.SuiteRunner.privateRun(SuiteRunner.java:291)
	at org.testng.SuiteRunner.run(SuiteRunner.java:240)
	at org.testng.SuiteRunnerWorker.runSuite(SuiteRunnerWorker.java:52)
	at org.testng.SuiteRunnerWorker.run(SuiteRunnerWorker.java:86)
	at org.testng.TestNG.runSuitesSequentially(TestNG.java:1224)
	at org.testng.TestNG.runSuitesLocally(TestNG.java:1149)
	at org.testng.TestNG.run(TestNG.java:1057)
	at org.testng.remote.RemoteTestNG.run(RemoteTestNG.java:111)
	at org.testng.remote.RemoteTestNG.initAndRun(RemoteTestNG.java:204)
	at org.testng.remote.RemoteTestNG.main(RemoteTestNG.java:175)
]]>
            </full-stacktrace>
          </exception> <!-- java.lang.AssertionError -->
          <reporter-output>
          </reporter-output>
        </test-method> <!-- verifyBlogTitle -->
        <test-method status="PASS" signature="tearDown(org.testng.ITestResult)[pri:0, instance:extentreports.extentreports.test2_VerifyTitle@49e4cb85]" name="tearDown" is-config="true" duration-ms="813" started-at="2015-10-14T13:12:14Z" finished-at="2015-10-14T13:12:15Z">
          <params>
            <param index="0">
              <value>
                <![CDATA[[TestResult name=verifyBlogTitle status=FAILURE method=test2_VerifyTitle.verifyBlogTitle()[pri:0, instance:extentreports.extentreports.test2_VerifyTitle@49e4cb85] output={null}]]]>
              </value>
            </param>
          </params>
          <reporter-output>
          </reporter-output>
        </test-method> <!-- tearDown -->
      </class> <!-- extentreports.extentreports.test2_VerifyTitle -->
      <class name="extentreports.extentreports.test1_VerifyTitle">
        <test-method status="FAIL" signature="verifyBlogTitle()[pri:0, instance:extentreports.extentreports.test1_VerifyTitle@511baa65]" name="verifyBlogTitle" duration-ms="23413" started-at="2015-10-14T13:11:25Z" finished-at="2015-10-14T13:11:49Z">
          <exception class="java.lang.AssertionError">
            <message>
              <![CDATA[expected [true] but found [false]]]>
            </message>
            <full-stacktrace>
              <![CDATA[java.lang.AssertionError: expected [true] but found [false]
	at org.testng.Assert.fail(Assert.java:94)
	at org.testng.Assert.failNotEquals(Assert.java:494)
	at org.testng.Assert.assertTrue(Assert.java:42)
	at org.testng.Assert.assertTrue(Assert.java:52)
	at extentreports.extentreports.test1_VerifyTitle.verifyBlogTitle(test1_VerifyTitle.java:40)
	at sun.reflect.NativeMethodAccessorImpl.invoke0(Native Method)
	at sun.reflect.NativeMethodAccessorImpl.invoke(NativeMethodAccessorImpl.java:62)
	at sun.reflect.DelegatingMethodAccessorImpl.invoke(DelegatingMethodAccessorImpl.java:43)
	at java.lang.reflect.Method.invoke(Method.java:483)
	at org.testng.internal.MethodInvocationHelper.invokeMethod(MethodInvocationHelper.java:84)
	at org.testng.internal.Invoker.invokeMethod(Invoker.java:714)
	at org.testng.internal.Invoker.invokeTestMethod(Invoker.java:901)
	at org.testng.internal.Invoker.invokeTestMethods(Invoker.java:1231)
	at org.testng.internal.TestMethodWorker.invokeTestMethods(TestMethodWorker.java:127)
	at org.testng.internal.TestMethodWorker.run(TestMethodWorker.java:111)
	at org.testng.TestRunner.privateRun(TestRunner.java:767)
	at org.testng.TestRunner.run(TestRunner.java:617)
	at org.testng.SuiteRunner.runTest(SuiteRunner.java:334)
	at org.testng.SuiteRunner.runSequentially(SuiteRunner.java:329)
	at org.testng.SuiteRunner.privateRun(SuiteRunner.java:291)
	at org.testng.SuiteRunner.run(SuiteRunner.java:240)
	at org.testng.SuiteRunnerWorker.runSuite(SuiteRunnerWorker.java:52)
	at org.testng.SuiteRunnerWorker.run(SuiteRunnerWorker.java:86)
	at org.testng.TestNG.runSuitesSequentially(TestNG.java:1224)
	at org.testng.TestNG.runSuitesLocally(TestNG.java:1149)
	at org.testng.TestNG.run(TestNG.java:1057)
	at org.testng.remote.RemoteTestNG.run(RemoteTestNG.java:111)
	at org.testng.remote.RemoteTestNG.initAndRun(RemoteTestNG.java:204)
	at org.testng.remote.RemoteTestNG.main(RemoteTestNG.java:175)
]]>
            </full-stacktrace>
          </exception> <!-- java.lang.AssertionError -->
          <reporter-output>
          </reporter-output>
        </test-method> <!-- verifyBlogTitle -->
        <test-method status="PASS" signature="tearDown(org.testng.ITestResult)[pri:0, instance:extentreports.extentreports.test1_VerifyTitle@511baa65]" name="tearDown" is-config="true" duration-ms="693" started-at="2015-10-14T13:11:49Z" finished-at="2015-10-14T13:11:49Z">
          <params>
            <param index="0">
              <value>
                <![CDATA[[TestResult name=verifyBlogTitle status=FAILURE method=test1_VerifyTitle.verifyBlogTitle()[pri:0, instance:extentreports.extentreports.test1_VerifyTitle@511baa65] output={null}]]]>
              </value>
            </param>
          </params>
          <reporter-output>
          </reporter-output>
        </test-method> <!-- tearDown -->
      </class> <!-- extentreports.extentreports.test1_VerifyTitle -->
    </test> <!-- Test -->
  </suite> <!-- Suite -->
</testng-results>
